<mujoco>
    <size njmax="3000" nconmax="1000"/>
    <option timestep="0.002"/>
    <default>
        <geom condim="1" density="1" rgba="1 0 0 1"/>
        <motor ctrlrange="-1 1" ctrllimited="true" forcerange="-1 1" forcelimited="true" gear="0.5 0 0 0 0 0"/>
    </default>
    <worldbody>
        <geom name="floor" size="5 5 0.1" type="plane" condim="6"/>
        <body name="robot" pos="0 0 .1">
            <camera name="vision" pos="0 0 .15" xyaxes="0 -1 0 .4 0 1" fovy="90"/>    
            <geom name="base_box" type="box" size="0.2 0.2 0.1"/>
            <site name="robot" rgba="1 0 0 .1"/>
            <joint name="base_rotation" type="hinge" stiffness="1"/>
            <body name="lower_arm">
                <joint name="lower_arm_bend" type="hinge" axis="1 0 0" stiffness="1"/>
                <geom name="lower_arm_pill" type="capsule" fromto="0 0 0 0 0 1" size="0.1 0"/>
                <body name="upper_arm" pos="0 0 1">
                    <joint name="upper_arm_bend" type="hinge" axis="1 0 0" stiffness="1"/>
                    <geom name="upper_arm_pill" type="capsule" fromto="0 0 0 0 0 1" size="0.05 0"/>
                    <body name="palm"  euler="0 0 90" pos="0 0 1.05">
                        <geom name="palm" type="box" size="0.1 0.1 0.01"/>
                        <body name="lower_palm" pos="0 0.1 0">
                            <joint name="lower_palm_bend" type="hinge" axis="1 0 0" stiffness="1"/>
                            <geom name="lower_palm_base" type="box" pos="0 0.03 0.07" size="0.1 0.01 0.08 " quat="1 -0.25 0 0"/>
                            <geom name="lower_palm_tip" type="box" pos="0 0.05 0.19" size="0.1 0.06 0.01" quat="1 -0.7 0 0"/>
                        </body>
                        <body name="upper_palm" pos="0 -0.1 0" euler="0 0 180">
                            <joint name="upper_palm_bend" type="hinge" axis="1 0 0" stiffness="1"/>
                            <geom name="upper_palm_base" type="box" pos="0 0.03 0.07" size="0.1 0.01 0.08 " quat="1 -0.25 0 0"/>
                            <geom name="upper_palm_tip" type="box" pos="0 0.05 0.19" size="0.1 0.06 0.01" quat="1 -0.7 0 0"/>
                        </body>
                    </body>
                </body>
            </body>
        </body>
    </worldbody>
    <sensor>
        <!-- Used for observation -->
        <accelerometer site="robot" name="accelerometer"/>
        <velocimeter site="robot" name="velocimeter"/>
        <gyro site="robot" name="gyro"/>
        <magnetometer site="robot" name="magnetometer"/>

        <!-- Used for intrinsic constraints -->
        <subtreecom body="robot" name="subtreecom"/>
        <subtreelinvel body="robot" name="subtreelinvel"/>
        <subtreeangmom body="robot" name="subtreeangmom"/>
    </sensor>
    <actuator>
        <motor joint="base_rotation" gear="10 0 0 0 0 0"/>
        <motor joint="lower_arm_bend" gear="4 0 0 0 0 0"/>
        <motor joint="upper_arm_bend" gear="0.1 0 0 0 0 0"/>
        <motor joint="lower_palm_bend" gear="0.01 0 0 0 0 0"/>
        <motor joint="upper_palm_bend" gear="0.01 0 0 0 0 0"/>
    </actuator>
</mujoco>
